Workbook

Sheet API_EG.ELC.ACCS.ZS_DS2_en_csv_v
A1: Data Source | B1: World Development Indicators
A3: Last Updated Date | B3: 46216
A5: Country Name | B5: Country Code | C5: Indicator Name | D5: Indicator Code | E5: 1960 | F5: 1961 | G5: 1962 | H5: 1963 | I5: 1964 | J5: 1965 | K5: 1966 | L5: 1967 | M5: 1968 | N5: 1969 | O5: 1970 | P5: 1971 | Q5: 1972 | R5: 1973 | S5: 1974 | T5: 1975 | U5: 1976 | V5: 1977 | W5: 1978 | X5: 1979 | Y5: 1980 | Z5: 1981 | AA5: 1982 | AB5: 1983 | AC5: 1984 | AD5: 1985 | AE5: 1986 | AF5: 1987 | AG5: 1988 | AH5: 1989 | AI5: 1990 | AJ5: 1991 | AK5: 1992 | AL5: 1993 | AM5: 1994 | AN5: 1995 | AO5: 1996 | AP5: 1997 | AQ5: 1998 | AR5: 1999 | AS5: 2000 | AT5: 2001 | AU5: 2002 | AV5: 2003 | AW5: 2004 | AX5: 2005 | AY5: 2006 | AZ5: 2007 | BA5: 2008 | BB5: 2009 | BC5: 2010 | BD5: 2011 | BE5: 2012 | BF5: 2013 | BG5: 2014 | BH5: 2015 | BI5: 2016 | BJ5: 2017 | BK5: 2018 | BL5: 2019 | BM5: 2020 | BN5: 2021 | BO5: 2022 | BP5: 2023 | BQ5: 2024 | BR5: 2025 | BS5: Region | BT5: Pop without Electricity
A6: Aruba | B6: ABW | C6: Access to electricity (% of population) | D6: EG.ELC.ACCS.ZS | AI6: 100 | AJ6: 99.153656 | AK6: 99.197128 | AL6: 99.239914 | AM6: 100 | AN6: 100 | AO6: 100 | AP6: 100 | AQ6: 100 | AR6: 100 | AS6: 91.7 | AT6: 100 | AU6: 100 | AV6: 100 | AW6: 100 | AX6: 100 | AY6: 100 | AZ6: 100 | BA6: 100 | BB6: 100 | BC6: 93.4 | BD6: 100 | BE6: 100 | BF6: 100 | BG6: 100 | BH6: 100 | BI6: 100 | BJ6: 100 | BK6: 100 | BL6: 100 | BM6: 100 | BN6: 100 | BO6: 99.9 | BP6: 100 | BQ6: 100 | BS6: =VLOOKUP(B6, Metadata!A:B, 2, FALSE) -> Latin America & Caribbean | BT6: =VLOOKUP(B6,Population!A:B,2,FALSE)*(1-BP6/100) -> 0
A7: Africa Eastern and Southern | B7: AFE | C7: Access to electricity (% of population) | D7: EG.ELC.ACCS.ZS | AS7: 19.917256 | AT7: 19.944277 | AU7: 21.548647 | AV7: 22.493217 | AW7: 23.724455 | AX7: 23.449539 | AY7: 25.172482 | AZ7: 26.795145 | BA7: 25.908845 | BB7: 26.187846 | BC7: 27.414954 | BD7: 28.909756 | BE7: 31.673427 | BF7: 31.723574 | BG7: 31.871956 | BH7: 33.922276 | BI7: 38.859598 | BJ7: 40.223744 | BK7: 43.035073 | BL7: 44.390861 | BM7: 46.282371 | BN7: 48.127211 | BO7: 48.742043 | BP7: 50.667516 | BQ7: 52.598171 | BS7: =VLOOKUP(B7, Metadata!A:B, 2, FALSE)
A8: Afghanistan | B8: AFG | C8: Access to electricity (% of population) | D8: EG.ELC.ACCS.ZS | AS8: 4.4 | AT8: 9.3 | AU8: 14.1 | AV8: 19 | AW8: 23.8 | AX8: 28.7 | AY8: 33.5 | AZ8: 38.4 | BA8: 42.4 | BB8: 48.3 | BC8: 42.7 | BD8: 43.2 | BE8: 69.1 | BF8: 68 | BG8: 89.5 | BH8: 71.5 | BI8: 97.7 | BJ8: 97.7 | BK8: 93.4 | BL8: 97.7 | BM8: 97.7 | BN8: 97.7 | BO8: 85.3 | BP8: 85.3 | BQ8: 87.8 | BS8: =VLOOKUP(B8, Metadata!A:B, 2, FALSE) -> Middle East & North Africa
A9: Africa Western and Central | B9: AFW | C9: Access to electricity (% of population) | D9: EG.ELC.ACCS.ZS | AL9: 31.653469 | AM9: 32.692208 | AN9: 33.694835 | AO9: 32.697395 | AP9: 32.52392 | AQ9: 33.537369 | AR9: 34.918951 | AS9: 34.268837 | AT9: 35.344367 | AU9: 35.828608 | AV9: 39.983091 | AW9: 37.611968 | AX9: 37.944506 | AY9: 39.969426 | AZ9: 40.879148 | BA9: 41.87867 | BB9: 42.01236 | BC9: 41.964455 | BD9: 46.069034 | BE9: 44.192408 | BF9: 47.202123 | BG9: 47.770081 | BH9: 46.865483 | BI9: 51.051636 | BJ9: 48.902228 | BK9: 51.338199 | BL9: 51.289374 | BM9: 51.851866 | BN9: 54.366012 | BO9: 55.585594 | BP9: 57.064737 | BQ9: 58.822166 | BS9: =VLOOKUP(B9, Metadata!A:B, 2, FALSE)
A10: Angola | B10: AGO | C10: Access to electricity (% of population) | D10: EG.ELC.ACCS.ZS | AS10: 24.2 | AT10: 20 | AU10: 26.3 | AV10: 27.4 | AW10: 28.4 | AX10: 29.4 | AY10: 30.5 | AZ10: 37.5 | BA10: 38.5 | BB10: 33.8 | BC10: 35 | BD10: 34.6 | BE10: 37.3 | BF10: 38.4 | BG10: 32 | BH10: 42 | BI10: 41.8 | BJ10: 42.9 | BK10: 45.3 | BL10: 45.6 | BM10: 47 | BN10: 48.2 | BO10: 48.5 | BP10: 51.1 | BQ10: 55.5 | BS10: =VLOOKUP(B10, Metadata!A:B, 2, FALSE) -> Sub-Saharan Africa | BT10: =VLOOKUP(B6,Population!A:B,2,FALSE)*(1-BP6/100) -> 0
A11: Albania | B11: ALB | C11: Access to electricity (% of population) | D11: EG.ELC.ACCS.ZS | AI11: 100 | AJ11: 100 | AK11: 100 | AL11: 100 | AM11: 100 | AN11: 100 | AO11: 100 | AP11: 100 | AQ11: 100 | AR11: 100 | AS11: 99.4 | AT11: 99.4 | AU11: 99.4 | AV11: 99.4 | AW11: 99.4 | AX11: 99.4 | AY11: 99.4 | AZ11: 99.4 | BA11: 100 | BB11: 99.6 | BC11: 99.6 | BD11: 99.7 | BE11: 99.9 | BF11: 99.9 | BG11: 100 | BH11: 100 | BI11: 99.9 | BJ11: 99.9 | BK11: 100 | BL11: 100 | BM11: 100 | BN11: 100 | BO11: 100 | BP11: 100 | BQ11: 100 | BS11: =VLOOKUP(B11, Metadata!A:B, 2, FALSE) -> Europe & Central Asia
A12: Andorra | B12: AND | C12: Access to electricity (% of population) | D12: EG.ELC.ACCS.ZS | AI12: 100 | AJ12: 100 | AK12: 100 | AL12: 100 | AM12: 100 | AN12: 100 | AO12: 100 | AP12: 100 | AQ12: 100 | AR12: 100 | AS12: 100 | AT12: 100 | AU12: 100 | AV12: 100 | AW12: 100 | AX12: 100 | AY12: 100 | AZ12: 100 | BA12: 100 | BB12: 100 | BC12: 100 | BD12: 100 | BE12: 100 | BF12: 100 | BG12: 100 | BH12: 100 | BI12: 100 | BJ12: 100 | BK12: 100 | BL12: 100 | BM12: 100 | BN12: 100 | BO12: 100 | BP12: 100 | BQ12: 100 | BS12: =VLOOKUP(B12, Metadata!A:B, 2, FALSE) -> Europe & Central Asia
A13: Arab World | B13: ARB | C13: Access to electricity (% of population) | D13: EG.ELC.ACCS.ZS | AP13: 76.611777 | AQ13: 77.541255 | AR13: 78.156404 | AS13: 80.458667 | AT13: 81.354794 | AU13: 81.323622 | AV13: 82.342222 | AW13: 82.279525 | AX13: 83.076767 | AY13: 85.284394 | AZ13: 83.626764 | BA13: 83.275564 | BB13: 84.159729 | BC13: 86.921503 | BD13: 87.172694 | BE13: 86.847867 | BF13: 88.96163 | BG13: 88.406777 | BH13: 88.661643 | BI13: 89.186171 | BJ13: 90.351067 | BK13: 88.689841 | BL13: 89.928996 | BM13: 90.241777 | BN13: 90.434095 | BO13: 90.654518 | BP13: 91.64543 | BQ13: 92.165918 | BS13: =VLOOKUP(B13, Metadata!A:B, 2, FALSE)
A14: United Arab Emirates | B14: ARE | C14: Access to electricity (% of population) | D14: EG.ELC.ACCS.ZS | AI14: 100 | AJ14: 100 | AK14: 100 | AL14: 100 | AM14: 100 | AN14: 100 | AO14: 100 | AP14: 100 | AQ14: 100 | AR14: 100 | AS14: 100 | AT14: 100 | AU14: 100 | AV14: 100 | AW14: 100 | AX14: 100 | AY14: 100 | AZ14: 100 | BA14: 100 | BB14: 100 | BC14: 100 | BD14: 100 | BE14: 100 | BF14: 100 | BG14: 100 | BH14: 100 | BI14: 100 | BJ14: 100 | BK14: 100 | BL14: 100 | BM14: 100 | BN14: 100 | BO14: 100 | BP14: 100 | BQ14: 100 | BS14: =VLOOKUP(B14, Metadata!A:B, 2, FALSE) -> Middle East & North Africa
A15: Argentina | B15: ARG | C15: Access to electricity (% of population) | D15: EG.ELC.ACCS.ZS | AI15: 92.1548 | AJ15: 92.492188 | AK15: 92.829453 | AL15: 93.166046 | AM15: 93.501274 | AN15: 93.834465 | AO15: 94.16494 | AP15: 94.492012 | AQ15: 94.815002 | AR15: 95.133156 | AS15: 95.7 | AT15: 95.5 | AU15: 96.1 | AV15: 96.3 | AW15: 96.5 | AX15: 96.7 | AY15: 97 | AZ15: 97.2 | BA15: 97.5 | BB15: 97.8 | BC15: 98.8 | BD15: 99 | BE15: 99.1 | BF15: 99.3 | BG15: 100 | BH15: 99.7 | BI15: 99.9 | BJ15: 100 | BK15: 100 | BL15: 100 | BM15: 100 | BN15: 100 | BO15: 100 | BP15: 100 | BQ15: 98.4 | BS15: =VLOOKUP(B15, Metadata!A:B, 2, FALSE) -> Latin America & Caribbean
A16: Armenia | B16: ARM | C16: Access to electricity (% of population) | D16: EG.ELC.ACCS.ZS | AS16: 98.9 | AT16: 100 | AU16: 98 | AV16: 99.1 | AW16: 99.1 | AX16: 99.8 | AY16: 99.1 | AZ16: 99.2 | BA16: 99.2 | BB16: 99.3 | BC16: 99.8 | BD16: 99.5 | BE16: 99.5 | BF16: 99.4 | BG16: 99.7 | BH16: 100 | BI16: 99.8 | BJ16: 99.7 | BK16: 99.9 | BL16: 100 | BM16: 100 | BN16: 100 | BO16: 100 | BP16: 100 | BQ16: 100 | BS16: =VLOOKUP(B16, Metadata!A:B, 2, FALSE) -> Europe & Central Asia
A17: American Samoa | B17: ASM | C17: Access to electricity (% of population) | D17: EG.ELC.ACCS.ZS | BS17: =VLOOKUP(B17, Metadata!A:B, 2, FALSE) -> East Asia & Pacific
A18: Antigua and Barbuda | B18: ATG | C18: Access to electricity (% of population) | D18: EG.ELC.ACCS.ZS | AI18: 95.763046 | AJ18: 95.940651 | AK18: 96.118134 | AL18: 96.294945 | AM18: 96.47039 | AN18: 96.643799 | AO18: 96.814484 | AP18: 96.981773 | AQ18: 97.144981 | AR18: 97.303352 | AS18: 97.7 | AT18: 97.7 | AU18: 100 | AV18: 97.9 | AW18: 97.9 | AX18: 92.2 | AY18: 100 | AZ18: 100 | BA18: 100 | BB18: 98.5 | BC18: 98.7 | BD18: 94.6 | BE18: 100 | BF18: 100 | BG18: 100 | BH18: 100 | BI18: 100 | BJ18: 100 | BK18: 100 | BL18: 100 | BM18: 100 | BN18: 100 | BO18: 100 | BP18: 100 | BQ18: 100 | BS18: =VLOOKUP(B18, Metadata!A:B, 2, FALSE) -> Latin America & Caribbean
A19: Australia | B19: AUS | C19: Access to electricity (% of population) | D19: EG.ELC.ACCS.ZS | AI19: 100 | AJ19: 100 | AK19: 100 | AL19: 100 | AM19: 100 | AN19: 100 | AO19: 100 | AP19: 100 | AQ19: 100 | AR19: 100 | AS19: 100 | AT19: 100 | AU19: 100 | AV19: 100 | AW19: 100 | AX19: 100 | AY19: 100 | AZ19: 100 | BA19: 100 | BB19: 100 | BC19: 100 | BD19: 100 | BE19: 100 | BF19: 100 | BG19: 100 | BH19: 100 | BI19: 100 | BJ19: 100 | BK19: 100 | BL19: 100 | BM19: 100 | BN19: 100 | BO19: 100 | BP19: 100 | BQ19: 100 | BS19: =VLOOKUP(B19, Metadata!A:B, 2, FALSE) -> East Asia & Pacific
A20: Austria | B20: AUT | C20: Access to electricity (% of population) | D20: EG.ELC.ACCS.ZS | AI20: 100 | AJ20: 100 | AK20: 100 | AL20: 100 | AM20: 100 | AN20: 100 | AO20: 100 | AP20: 100 | AQ20: 100 | AR20: 100 | AS20: 100 | AT20: 100 | AU20: 100 | AV20: 100 | AW20: 100 | AX20: 100 | AY20: 100 | AZ20: 100 | BA20: 100 | BB20: 100 | BC20: 100 | BD20: 100 | BE20: 100 | BF20: 100 | BG20: 100 | BH20: 100 | BI20: 100 | BJ20: 100 | BK20: 100 | BL20: 100 | BM20: 100 | BN20: 100 | BO20: 100 | BP20: 100 | BQ20: 100 | BS20: =VLOOKUP(B20, Metadata!A:B, 2, FALSE) -> Europe & Central Asia
A21: Azerbaijan | B21: AZE | C21: Access to electricity (% of population) | D21: EG.ELC.ACCS.ZS | AR21: 97 | AS21: 98.9 | AT21: 98.6 | AU21: 100 | AV21: 98.8 | AW21: 99 | AX21: 99.1 | AY21: 99.5 | AZ21: 99.5 | BA21: 99.7 | BB21: 99.9 | BC21: 99.9 | BD21: 99.9 | BE21: 100 | BF21: 100 | BG21: 100 | BH21: 100 | BI21: 100 | BJ21: 100 | BK21: 100 | BL21: 100 | BM21: 100 | BN21: 100 | BO21: 100 | BP21: 100 | BQ21: 100 | BS21: =VLOOKUP(B21, Metadata!A:B, 2, FALSE) -> Europe & Central Asia
A22: Burundi | B22: BDI | C22: Access to electricity (% of population) | D22: EG.ELC.ACCS.ZS | AQ22: 3.9 | AR22: 2.0709493 | AS22: 2.5 | AT22: 2.8 | AU22: 3.1 | AV22: 3.4 | AW22: 3.7 | AX22: 3.2 | AY22: 2.7 | AZ22: 4.7 | BA22: 4.8 | BB22: 5.4 | BC22: 5.3 | BD22: 6.2 | BE22: 6.5 | BF22: 6.9 | BG22: 7 | BH22: 7.9 | BI22: 8.5 | BJ22: 9.3 | BK22: 9.5 | BL22: 9.8 | BM22: 9.1 | BN22: 10.2 | BO22: 10.3 | BP22: 11.6 | BQ22: 20.1 | BS22: =VLOOKUP(B22, Metadata!A:B, 2, FALSE) -> Sub-Saharan Africa | BT22: =VLOOKUP(B18,Population!A:B,2,FALSE)*(1-BP18/100) -> 0
A23: Belgium | B23: BEL | C23: Access to electricity (% of population) | D23: EG.ELC.ACCS.ZS | AI23: 100 | AJ23: 100 | AK23: 100 | AL23: 100 | AM23: 100 | AN23: 100 | AO23: 100 | AP23: 100 | AQ23: 100 | AR23: 100 | AS23: 100 | AT23: 100 | AU23: 100 | AV23: 100 | AW23: 100 | AX23: 100 | AY23: 100 | AZ23: 100 | BA23: 100 | BB23: 100 | BC23: 100 | BD23: 100 | BE23: 100 | BF23: 100 | BG23: 100 | BH23: 100 | BI23: 100 | BJ23: 100 | BK23: 100 | BL23: 100 | BM23: 100 | BN23: 100 | BO23: 100 | BP23: 100 | BQ23: 100 | BS23: =VLOOKUP(B23, Metadata!A:B, 2, FALSE) -> Europe & Central Asia
A24: Benin | B24: BEN | C24: Access to electricity (% of population) | D24: EG.ELC.ACCS.ZS | AO24: 14.5 | AP24: 18.589626 | AQ24: 19.578255 | AR24: 20.562042 | AS24: 21.5 | AT24: 21.9 | AU24: 23.4 | AV24: 24.3 | AW24: 25.2 | AX24: 26.1 | AY24: 27.9 | AZ24: 28 | BA24: 29 | BB24: 30 | BC24: 34.2 | BD24: 36.9 | BE24: 38.4 | BF24: 34.7 | BG24: 34.1 | BH24: 29.6 | BI24: 37 | BJ24: 34.5 | BK24: 39 | BL24: 40 | BM24: 41 | BN24: 42 | BO24: 56.5 | BP24: 57 | BQ24: 59 | BS24: =VLOOKUP(B24, Metadata!A:B, 2, FALSE) -> Sub-Saharan Africa | BT24: =VLOOKUP(B20,Population!A:B,2,FALSE)*(1-BP20/100) -> 0
A25: Burkina Faso | B25: BFA | C25: Access to electricity (% of population) | D25: EG.ELC.ACCS.ZS | AL25: 6.1 | AM25: 6.12501 | AN25: 6.6253328 | AO25: 7.1229362 | AP25: 7.6171398 | AQ25: 8.1072645 | AR25: 6.9 | AS25: 9.1 | AT25: 9.5 | AU25: 9.9 | AV25: 11.4 | AW25: 10.7 | AX25: 11.1 | AY25: 11.6 | AZ25: 12 | BA25: 12.5 | BB25: 12.6 | BC25: 13.1 | BD25: 14.8 | BE25: 15.1 | BF25: 15.4 | BG25: 19.2 | BH25: 16.2 | BI25: 16.6 | BJ25: 17 | BK25: 14.4 | BL25: 17.6 | BM25: 18.5 | BN25: 19 | BO25: 19.5 | BP25: 21.7 | BQ25: 34 | BS25: =VLOOKUP(B25, Metadata!A:B, 2, FALSE) -> Sub-Saharan Africa | BT25: =VLOOKUP(B21,Population!A:B,2,FALSE)*(1-BP21/100) -> 0
A26: Bangladesh | B26: BGD | C26: Access to electricity (% of population) | D26: EG.ELC.ACCS.ZS | AJ26: 14.29 | AK26: 9.9054193 | AL26: 12.71788 | AM26: 17.8 | AN26: 18.338045 | AO26: 21.144386 | AP26: 22.4 | AQ26: 26.746193 | AR26: 29.540215 | AS26: 32 | AT26: 35 | AU26: 37.8 | AV26: 40.5 | AW26: 40.6 | AX26: 44.2 | AY26: 50.5 | AZ26: 46.5 | BA26: 54.3 | BB26: 57.1 | BC26: 55.3 | BD26: 59.6 | BE26: 65.5 | BF26: 61.5 | BG26: 62.4 | BH26: 74 | BI26: 75.9 | BJ26: 88 | BK26: 86.9 | BL26: 92.2 | BM26: 96.2 | BN26: 99 | BO26: 99.4 | BP26: 99.5 | BQ26: 99.5 | BS26: =VLOOKUP(B26, Metadata!A:B, 2, FALSE) -> South Asia
A27: Bulgaria | B27: BGR | C27: Access to electricity (% of population) | D27: EG.ELC.ACCS.ZS | AI27: 100 | AJ27: 100 | AK27: 100 | AL27: 100 | AM27: 100 | AN27: 100 | AO27: 100 | AP27: 100 | AQ27: 100 | AR27: 100 | AS27: 88.1 | AT27: 88.6 | AU27: 89.1 | AV27: 89.6 | AW27: 90.1 | AX27: 90.6 | AY27: 91.2 | AZ27: 91.7 | BA27: 92.3 | BB27: 92.9 | BC27: 93.5 | BD27: 94.1 | BE27: 94.7 | BF27: 95.3 | BG27: 95.9 | BH27: 96.6 | BI27: 97.3 | BJ27: 98.1 | BK27: 98.7 | BL27: 99.2 | BM27: 99.7 | BN27: 99.8 | BO27: 100 | BP27: 100 | BQ27: 100 | BS27: =VLOOKUP(B27, Metadata!A:B, 2, FALSE) -> Europe & Central Asia
A28: Bahrain | B28: BHR | C28: Access to electricity (% of population) | D28: EG.ELC.ACCS.ZS | AI28: 99.941399 | AJ28: 99.967392 | AK28: 99.987183 | AL28: 99.997139 | AM28: 99.999771 | AN28: 100 | AO28: 100 | AP28: 100 | AQ28: 100 | AR28: 100 | AS28: 100 | AT28: 100 | AU28: 100 | AV28: 100 | AW28: 100 | AX28: 100 | AY28: 100 | AZ28: 100 | BA28: 100 | BB28: 100 | BC28: 100 | BD28: 100 | BE28: 100 | BF28: 100 | BG28: 100 | BH28: 100 | BI28: 100 | BJ28: 100 | BK28: 100 | BL28: 100 | BM28: 100 | BN28: 100 | BO28: 100 | BP28: 100 | BQ28: 100 | BS28: =VLOOKUP(B28, Metadata!A:B, 2, FALSE) -> Middle East & North Africa
A29: Bahamas, The | B29: BHS | C29: Access to electricity (% of population) | D29: EG.ELC.ACCS.ZS | AI29: 100 | AJ29: 100 | AK29: 100 | AL29: 100 | AM29: 100 | AN29: 100 | AO29: 100 | AP29: 100 | AQ29: 100 | AR29: 100 | AS29: 100 | AT29: 100 | AU29: 100 | AV29: 100 | AW29: 100 | AX29: 100 | AY29: 100 | AZ29: 100 | BA29: 100 | BB29: 100 | BC29: 100 | BD29: 100 | BE29: 100 | BF29: 100 | BG29: 100 | BH29: 100 | BI29: 100 | BJ29: 100 | BK29: 100 | BL29: 100 | BM29: 100 | BN29: 100 | BO29: 100 | BP29: 100 | BQ29: 100 | BS29: =VLOOKUP(B29, Metadata!A:B, 2, FALSE) -> Latin America & Caribbean
A30: Bosnia and Herzegovina | B30: BIH | C30: Access to electricity (% of population) | D30: EG.ELC.ACCS.ZS | AI30: 100 | AJ30: 100 | AK30: 100 | AL30: 100 | AM30: 100 | AN30: 100 | AO30: 100 | AP30: 100 | AQ30: 100 | AR30: 100 | AS30: 99 | AT30: 99.4 | AU30: 98.5 | AV30: 99 | AW30: 99.1 | AX30: 99.1 | AY30: 99.4 | AZ30: 99.7 | BA30: 99.3 | BB30: 99.4 | BC30: 99.5 | BD30: 99.7 | BE30: 99.7 | BF30: 99.5 | BG30: 99.9 | BH30: 99.7 | BI30: 100 | BJ30: 100 | BK30: 100 | BL30: 100 | BM30: 100 | BN30: 100 | BO30: 100 | BP30: 100 | BQ30: 100 | BS30: =VLOOKUP(B30, Metadata!A:B, 2, FALSE) -> Europe & Central Asia
A31: Belarus | B31: BLR | C31: Access to electricity (% of population) | D31: EG.ELC.ACCS.ZS | AI31: 100 | AJ31: 100 | AK31: 100 | AL31: 100 | AM31: 100 | AN31: 100 | AO31: 100 | AP31: 100 | AQ31: 100 | AR31: 100 | AS31: 89 | AT31: 89.5 | AU31: 90 | AV31: 90.5 | AW31: 91 | AX31: 91.5 | AY31: 92.1 | AZ31: 92.6 | BA31: 93.2 | BB31: 93.8 | BC31: 94.4 | BD31: 95 | BE31: 95.6 | BF31: 96.2 | BG31: 96.8 | BH31: 97.4 | BI31: 98 | BJ31: 98.7 | BK31: 99.3 | BL31: 100 | BM31: 100 | BN31: 100 | BO31: 100 | BP31: 100 | BQ31: 100 | BS31: =VLOOKUP(B31, Metadata!A:B, 2, FALSE) -> Europe & Central Asia
A32: Belize | B32: BLZ | C32: Access to electricity (% of population) | D32: EG.ELC.ACCS.ZS | AJ32: 67 | AK32: 72.224915 | AL32: 73.123329 | AM32: 74.020386 | AN32: 74.915398 | AO32: 75.807693 | AP32: 76.696587 | AQ32: 77.581406 | AR32: 78.46138 | AS32: 79 | AT32: 80.2 | AU32: 81 | AV32: 81.8 | AW32: 82.6 | AX32: 83.5 | AY32: 91 | AZ32: 85.2 | BA32: 86.1 | BB32: 86.9 | BC32: 89.9 | BD32: 91.7 | BE32: 90.9 | BF32: 91.1 | BG32: 91.5 | BH32: 91.8 | BI32: 93.3 | BJ32: 94.2 | BK32: 91.7 | BL32: 92.7 | BM32: 96.8 | BN32: 97.7 | BO32: 98.6 | BP32: 99.6 | BQ32: 99.6 | BS32: =VLOOKUP(B32, Metadata!A:B, 2, FALSE) -> Latin America & Caribbean
A33: Bermuda | B33: BMU | C33: Access to electricity (% of population) | D33: EG.ELC.ACCS.ZS | AI33: 100 | AJ33: 100 | AK33: 100 | AL33: 100 | AM33: 100 | AN33: 100 | AO33: 100 | AP33: 100 | AQ33: 100 | AR33: 100 | AS33: 100 | AT33: 100 | AU33: 100 | AV33: 100 | AW33: 100 | AX33: 100 | AY33: 100 | AZ33: 100 | BA33: 100 | BB33: 100 | BC33: 100 | BD33: 100 | BE33: 100 | BF33: 100 | BG33: 100 | BH33: 100 | BI33: 100 | BJ33: 100 | BK33: 100 | BL33: 100 | BM33: 100 | BN33: 100 | BO33: 100 | BP33: 100 | BQ33: 100 | BS33: =VLOOKUP(B33, Metadata!A:B, 2, FALSE) -> North America
A34: Bolivia | B34: BOL | C34: Access to electricity (% of population) | D34: EG.ELC.ACCS.ZS | AK34: 60.027901 | AL34: 61.384029 | AM34: 64.1 | AN34: 64.09153 | AO34: 71 | AP34: 67.330431 | AQ34: 71.2 | AR34: 70.929888 | AS34: 70 | AT34: 69.3 | AU34: 64 | AV34: 72.3 | AW34: 75.9 | AX34: 68.3 | AY34: 76.2 | AZ34: 80.2 | BA34: 84.7 | BB34: 86.8 | BC34: 88 | BD34: 88.3 | BE34: 90.4 | BF34: 89.5 | BG34: 90 | BH34: 91.5 | BI34: 91.8 | BJ34: 91.8 | BK34: 92.8 | BL34: 95.1 | BM34: 97.2 | BN34: 98.6 | BO34: 99.9 | BP34: 99.8 | BQ34: 96.6 | BS34: =VLOOKUP(B34, Metadata!A:B, 2, FALSE) -> Latin America & Caribbean
A35: Brazil | B35: BRA | C35: Access to electricity (% of population) | D35: EG.ELC.ACCS.ZS | AI35: 87.475116 | AJ35: 90.606544 | AK35: 88.803833 | AL35: 89.999927 | AM35: 91.883728 | AN35: 91.728598 | AO35: 92.867095 | AP35: 93.354139 | AQ35: 94.193812 | AR35: 94.76296 | AS35: 94.4 | AT35: 96 | AU35: 96.7 | AV35: 97 | AW35: 96.8 | AX35: 97.1 | AY35: 97.6 | AZ35: 98.1 | BA35: 98.5 | BB35: 98.9 | BC35: 98.6 | BD35: 99.3 | BE35: 99.5 | BF35: 99.6 | BG35: 99.7 | BH35: 99.7 | BI35: 99.7 | BJ35: 99.8 | BK35: 99.7 | BL35: 99.8 | BM35: 99.7 | BN35: 99.5 | BO35: 100 | BP35: 99.8 | BQ35: 99.8 | BS35: =VLOOKUP(B35, Metadata!A:B, 2, FALSE) -> Latin America & Caribbean
A36: Barbados | B36: BRB | C36: Access to electricity (% of population) | D36: EG.ELC.ACCS.ZS | AI36: 99.984253 | AJ36: 99.993439 | AK36: 99.998688 | AL36: 100 | AM36: 100 | AN36: 100 | AO36: 100 | AP36: 100 | AQ36: 100 | AR36: 100 | AS36: 100 | AT36: 100 | AU36: 100 | AV36: 100 | AW36: 99.9 | AX36: 99.9 | AY36: 100 | AZ36: 100 | BA36: 100 | BB36: 100 | BC36: 100 | BD36: 100 | BE36: 100 | BF36: 100 | BG36: 100 | BH36: 100 | BI36: 100 | BJ36: 100 | BK36: 100 | BL36: 100 | BM36: 100 | BN36: 100 | BO36: 100 | BP36: 100 | BQ36: 100 | BS36: =VLOOKUP(B36, Metadata!A:B, 2, FALSE) -> Latin America & Caribbean
A37: Brunei Darussalam | B37: BRN | C37: Access to electricity (% of population) | D37: EG.ELC.ACCS.ZS | AI37: 100 | AJ37: 100 | AK37: 100 | AL37: 100 | AM37: 100 | AN37: 100 | AO37: 100 | AP37: 100 | AQ37: 100 | AR37: 100 | AS37: 100 | AT37: 100 | AU37: 100 | AV37: 100 | AW37: 100 | AX37: 100 | AY37: 100 | AZ37: 100 | BA37: 100 | BB37: 100 | BC37: 100 | BD37: 100 | BE37: 100 | BF37: 100 | BG37: 100 | BH37: 100 | BI37: 100 | BJ37: 100 | BK37: 100 | BL37: 100 | BM37: 100 | BN37: 100 | BO37: 100 | BP37: 100 | BQ37: 100 | BS37: =VLOOKUP(B37, Metadata!A:B, 2, FALSE) -> East Asia & Pacific
A38: Bhutan | B38: BTN | C38: Access to electricity (% of population) | D38: EG.ELC.ACCS.ZS | AS38: 31.1 | AT38: 40.2 | AU38: 44.1 | AV38: 41.1 | AW38: 51.9 | AX38: 59.8 | AY38: 59.7 | AZ38: 71.8 | BA38: 67.6 | BB38: 71.5 | BC38: 73.3 | BD38: 81.8 | BE38: 91.5 | BF38: 87.4 | BG38: 91.4 | BH38: 95.4 | BI38: 99.3 | BJ38: 97.7 | BK38: 100 | BL38: 100 | BM38: 100 | BN38: 100 | BO38: 100 | BP38: 100 | BQ38: 100 | BS38: =VLOOKUP(B38, Metadata!A:B, 2, FALSE) -> South Asia
A39: Botswana | B39: BWA | C39: Access to electricity (% of population) | D39: EG.ELC.ACCS.ZS | AJ39: 10.1 | AK39: 9.3982267 | AL39: 11.642076 | AM39: 13.884566 | AN39: 16.125017 | AO39: 18.362747 | AP39: 20.597078 | AQ39: 22.82733 | AR39: 25.05274 | AS39: 26.5 | AT39: 24.8 | AU39: 27 | AV39: 33.1 | AW39: 35.3 | AX39: 37.5 | AY39: 39.7 | AZ39: 41.9 | BA39: 44.5 | BB39: 43.4 | BC39: 52 | BD39: 53.2 | BE39: 56 | BF39: 58 | BG39: 60 | BH39: 62.1 | BI39: 64.2 | BJ39: 67.4 | BK39: 68.3 | BL39: 70.1 | BM39: 71.8 | BN39: 73.7 | BO39: 75.9 | BP39: 76 | BQ39: 80.2 | BS39: =VLOOKUP(B39, Metadata!A:B, 2, FALSE) -> Sub-Saharan Africa | BT39: =VLOOKUP(B35,Population!A:B,2,FALSE)*(1-BP35/100) -> 422281.46
A40: Central African Republic | B40: CAF | C40: Access to electricity (% of population) | D40: EG.ELC.ACCS.ZS | AN40: 3 | AO40: 3.3349156 | AP40: 3.8302102 | AQ40: 4.3214254 | AR40: 4.8077984 | AS40: 6 | AT40: 5.7 | AU40: 6.1 | AV40: 6.6 | AW40: 7 | AX40: 7.4 | AY40: 7.8 | AZ40: 8.4 | BA40: 7.5 | BB40: 9.4 | BC40: 9.8 | BD40: 10.4 | BE40: 11 | BF40: 11.5 | BG40: 12 | BH40: 12.7 | BI40: 13.4 | BJ40: 14.1 | BK40: 14.6 | BL40: 14.3 | BM40: 15.4 | BN40: 15.7 | BO40: 15.7 | BP40: 17.6 | BQ40: 18.2 | BS40: =VLOOKUP(B40, Metadata!A:B, 2, FALSE) -> Sub-Saharan Africa | BT40: =VLOOKUP(B36,Population!A:B,2,FALSE)*(1-BP36/100) -> 0
A41: Canada | B41: CAN | C41: Access to electricity (% of population) | D41: EG.ELC.ACCS.ZS | AI41: 100 | AJ41: 100 | AK41: 100 | AL41: 100 | AM41: 100 | AN41: 100 | AO41: 100 | AP41: 100 | AQ41: 100 | AR41: 100 | AS41: 100 | AT41: 100 | AU41: 100 | AV41: 100 | AW41: 100 | AX41: 100 | AY41: 100 | AZ41: 100 | BA41: 100 | BB41: 100 | BC41: 100 | BD41: 100 | BE41: 100 | BF41: 100 | BG41: 100 | BH41: 100 | BI41: 100 | BJ41: 100 | BK41: 100 | BL41: 100 | BM41: 100 | BN41: 100 | BO41: 100 | BP41: 100 | BQ41: 100 | BS41: =VLOOKUP(B41, Metadata!A:B, 2, FALSE) -> North America
A42: Central Europe and the Baltics | B42: CEB | C42: Access to electricity (% of population) | D42: EG.ELC.ACCS.ZS | AI42: 100 | AJ42: 100 | AK42: 100 | AL42: 100 | AM42: 100 | AN42: 100 | AO42: 100 | AP42: 100 | AQ42: 100 | AR42: 100 | AS42: 97.926264 | AT42: 98.023538 | AU42: 98.141558 | AV42: 98.190797 | AW42: 98.26793 | AX42: 98.3207 | AY42: 98.424282 | AZ42: 98.527645 | BA42: 98.668857 | BB42: 98.85866 | BC42: 98.964427 | BD42: 99.068299 | BE42: 99.202836 | BF42: 99.308477 | BG42: 99.410769 | BH42: 99.538471 | BI42: 99.645914 | BJ42: 99.873687 | BK42: 99.876376 | BL42: 99.948035 | BM42: 99.980584 | BN42: 99.987012 | BO42: 100 | BP42: 100 | BQ42: 100 | BS42: =VLOOKUP(B42, Metadata!A:B, 2, FALSE)
...

Sheet Africa Analysis
A1: Madagascar | B1: MDG | C1: Access to electricity (% of population) | D1: EG.ELC.ACCS.ZS | E1: 39.4 | F1: Sub-Saharan Africa | G1: =VLOOKUP(B1,Population!A:B,2,FALSE)*(1-BP1/100) -> 31195932 | H1: =RANK(E2,E$2:E$49,1) -> 4 | I1: =RANK(G2,G$2:G$49,0) -> 20 | J1: =IFS(I2<=5,"High", I2<=15,"Moderate", TRUE,"Low") -> Low
A2: Chad | B2: TCD | C2: Access to electricity (% of population) | D2: EG.ELC.ACCS.ZS | E2: 12 | F2: Sub-Saharan Africa | G2: =VLOOKUP(B2,Population!A:B,2,FALSE)*(1-BP2/100) -> 19319064 | H2: =RANK(E3,E$2:E$49,1) -> 21 | I2: =RANK(G3,G$2:G$49,0) -> 32 | J2: =IFS(I3<=5,"High", I3<=15,"Moderate", TRUE,"Low") -> Low
A3: Eritrea | B3: ERI | C3: Access to electricity (% of population) | D3: EG.ELC.ACCS.ZS | E3: 54.4 | F3: Sub-Saharan Africa | G3: =VLOOKUP(B3,Population!A:B,2,FALSE)*(1-BP3/100) -> 3470390 | H3: =RANK(E4,E$2:E$49,1) -> 23 | I3: =RANK(G4,G$2:G$49,0) -> 16 | J3: =IFS(I4<=5,"High", I4<=15,"Moderate", TRUE,"Low") -> Low
A4: Mali | B4: MLI | C4: Access to electricity (% of population) | D4: EG.ELC.ACCS.ZS | E4: 54.5 | F4: Sub-Saharan Africa | G4: =VLOOKUP(B4,Population!A:B,2,FALSE)*(1-BP4/100) -> 23769127 | H4: =RANK(E5,E$2:E$49,1) -> 1 | I4: =RANK(G5,G$2:G$49,0) -> 27 | J4: =IFS(I5<=5,"High", I5<=15,"Moderate", TRUE,"Low") -> Low
A5: South Sudan | B5: SSD | C5: Access to electricity (% of population) | D5: EG.ELC.ACCS.ZS | E5: 5.4 | F5: Sub-Saharan Africa | G5: =VLOOKUP(B5,Population!A:B,2,FALSE)*(1-BP5/100) -> 11483374 | H5: =RANK(E6,E$2:E$49,1) -> 46 | I5: =RANK(G6,G$2:G$49,0) -> 41 | J5: =IFS(I6<=5,"High", I6<=15,"Moderate", TRUE,"Low") -> Moderate
A6: Mauritius | B6: MUS | C6: Access to electricity (% of population) | D6: EG.ELC.ACCS.ZS | E6: 100 | F6: Sub-Saharan Africa | G6: =VLOOKUP(B6,Population!A:B,2,FALSE)*(1-BP6/100) -> 1248647 | H6: =RANK(E7,E$2:E$49,1) -> 38 | I6: =RANK(G7,G$2:G$49,0) -> 6 | J6: =IFS(I7<=5,"High", I7<=15,"Moderate", TRUE,"Low") -> High
A7: Kenya | B7: KEN | C7: Access to electricity (% of population) | D7: EG.ELC.ACCS.ZS | E7: 76.2 | F7: Sub-Saharan Africa | G7: =VLOOKUP(B7,Population!A:B,2,FALSE)*(1-BP7/100) -> 55339003 | H7: =RANK(E8,E$2:E$49,1) -> 16 | I7: =RANK(G8,G$2:G$49,0) -> 5 | J7: =IFS(I8<=5,"High", I8<=15,"Moderate", TRUE,"Low") -> Low
A8: Tanzania | B8: TZA | C8: Access to electricity (% of population) | D8: EG.ELC.ACCS.ZS | E8: 48.3 | F8: Sub-Saharan Africa | G8: =VLOOKUP(B8,Population!A:B,2,FALSE)*(1-BP8/100) -> 66617606 | H8: =RANK(E9,E$2:E$49,1) -> 5 | I8: =RANK(G9,G$2:G$49,0) -> 19 | J8: =IFS(I9<=5,"High", I9<=15,"Moderate", TRUE,"Low") -> Low
A9: Malawi | B9: MWI | C9: Access to electricity (% of population) | D9: EG.ELC.ACCS.ZS | E9: 15.6 | F9: Sub-Saharan Africa | G9: =VLOOKUP(B9,Population!A:B,2,FALSE)*(1-BP9/100) -> 21104482 | H9: =RANK(E10,E$2:E$49,1) -> 44 | I9: =RANK(G10,G$2:G$49,0) -> 37 | J9: =IFS(I10<=5,"High", I10<=15,"Moderate", TRUE,"Low") -> Low
A10: Gabon | B10: GAB | C10: Access to electricity (% of population) | D10: EG.ELC.ACCS.ZS | E10: 94.1 | F10: Sub-Saharan Africa | G10: =VLOOKUP(B10,Population!A:B,2,FALSE)*(1-BP10/100) -> 2484789 | H10: =RANK(E11,E$2:E$49,1) -> 21 | I10: =RANK(G11,G$2:G$49,0) -> 32 | J10: =IFS(I11<=5,"High", I11<=15,"Moderate", TRUE,"Low") -> Low
A11: Eritrea | B11: ERI | C11: Access to electricity (% of population) | D11: EG.ELC.ACCS.ZS | E11: 54.4 | F11: Sub-Saharan Africa | G11: =VLOOKUP(B11,Population!A:B,2,FALSE)*(1-BP11/100) -> 3470390 | H11: =RANK(E12,E$2:E$49,1) -> 23 | I11: =RANK(G12,G$2:G$49,0) -> 16 | J11: =IFS(I12<=5,"High", I12<=15,"Moderate", TRUE,"Low") -> Low
A12: Mali | B12: MLI | C12: Access to electricity (% of population) | D12: EG.ELC.ACCS.ZS | E12: 54.5 | F12: Sub-Saharan Africa | G12: =VLOOKUP(B12,Population!A:B,2,FALSE)*(1-BP12/100) -> 23769127 | H12: =RANK(E13,E$2:E$49,1) -> 1 | I12: =RANK(G13,G$2:G$49,0) -> 27 | J12: =IFS(I13<=5,"High", I13<=15,"Moderate", TRUE,"Low") -> Moderate
... A26: Liberia | B26: LBR | C26: Access to electricity (% of population) | D26: EG.ELC.ACCS.ZS | E26: 32.5 | F26: Sub-Saharan Africa | G26: =VLOOKUP(B26,Population!A:B,2,FALSE)*(1-BP26/100) -> 5493031 | H26: =RANK(E27,E$2:E$49,1) -> 48 | I26: =RANK(G27,G$2:G$49,0) -> #VALUE! | J26: =IFS(I27<=5,"High", I27<=15,"Moderate", TRUE,"Low") -> High
A27: Country Name | B27: Country Code | C27: Indicator Name | D27: Indicator Code | E27: 2023 | F27: Region | G27: Pop without Electricity | H27: =RANK(E28,E$2:E$49,1) -> 28 | I27: =RANK(G28,G$2:G$49,0) -> 1 | J27: =IFS(I28<=5,"High", I28<=15,"Moderate", TRUE,"Low") -> Low
A28: Nigeria | B28: NGA | C28: Access to electricity (% of population) | D28: EG.ELC.ACCS.ZS | E28: 61.2 | F28: Sub-Saharan Africa | G28: =VLOOKUP(B28,Population!A:B,2,FALSE)*(1-BP28/100) -> 227882945 | H28: =RANK(E29,E$2:E$49,1) -> 36 | I28: =RANK(G29,G$2:G$49,0) -> 21 | J28: =IFS(I29<=5,"High", I29<=15,"Moderate", TRUE,"Low") -> Moderate
A29: Senegal | B29: SEN | C29: Access to electricity (% of population) | D29: EG.ELC.ACCS.ZS | E29: 74.2 | F29: Sub-Saharan Africa | G29: =VLOOKUP(B29,Population!A:B,2,FALSE)*(1-BP29/100) -> 18077573 | H29: =RANK(E30,E$2:E$49,1) -> 33 | I29: =RANK(G30,G$2:G$49,0) -> 14 | J29: =IFS(I30<=5,"High", I30<=15,"Moderate", TRUE,"Low") -> Low
A30: Cameroon | B30: CMR | C30: Access to electricity (% of population) | D30: EG.ELC.ACCS.ZS | E30: 72 | F30: Sub-Saharan Africa | G30: =VLOOKUP(B30,Population!A:B,2,FALSE)*(1-BP30/100) -> 28372687 | H30: =RANK(E31,E$2:E$49,1) -> 39 | I30: =RANK(G31,G$2:G$49,0) -> 46 | J30: =IFS(I31<=5,"High", I31<=15,"Moderate", TRUE,"Low") -> Low
A31: Sao Tome and Principe | B31: STP | C31: Access to electricity (% of population) | D31: EG.ELC.ACCS.ZS | E31: 81.3 | F31: Sub-Saharan Africa | G31: =VLOOKUP(B31,Population!A:B,2,FALSE)*(1-BP31/100) -> 230871 | H31: =RANK(E32,E$2:E$49,1) -> 30 | I31: =RANK(G32,G$2:G$49,0) -> 40 | J31: =IFS(I32<=5,"High", I32<=15,"Moderate", TRUE,"Low") -> Low
A32: Equatorial Guinea | B32: GNQ | C32: Access to electricity (% of population) | D32: EG.ELC.ACCS.ZS | E32: 66.9 | F32: Sub-Saharan Africa | G32: =VLOOKUP(B32,Population!A:B,2,FALSE)*(1-BP32/100) -> 1847549 | H32: =RANK(E33,E$2:E$49,1) -> 30 | I32: =RANK(G33,G$2:G$49,0) -> 35 | J32: =IFS(I33<=5,"High", I33<=15,"Moderate", TRUE,"Low") -> Low
A33: Gambia, The | B33: GMB | C33: Access to electricity (% of population) | D33: EG.ELC.ACCS.ZS | E33: 66.9 | F33: Sub-Saharan Africa | G33: =VLOOKUP(B33,Population!A:B,2,FALSE)*(1-BP33/100) -> 2697845 | H33: =RANK(E34,E$2:E$49,1) -> 46 | I33: =RANK(G34,G$2:G$49,0) -> 47 | J33: =IFS(I34<=5,"High", I34<=15,"Moderate", TRUE,"Low") -> Low
A34: Seychelles | B34: SYC | C34: Access to electricity (% of population) | D34: EG.ELC.ACCS.ZS | E34: 100 | F34: Sub-Saharan Africa | G34: =VLOOKUP(B34,Population!A:B,2,FALSE)*(1-BP34/100) -> 119773 | H34: =RANK(E35,E$2:E$49,1) -> 17 | I34: =RANK(G35,G$2:G$49,0) -> 23 | J34: =IFS(I35<=5,"High", I35<=15,"Moderate", TRUE,"Low") -> Moderate
A35: Guinea | B35: GIN | C35: Access to electricity (% of population) | D35: EG.ELC.ACCS.ZS | E35: 51.1 | F35: Sub-Saharan Africa | G35: =VLOOKUP(B35,Population!A:B,2,FALSE)*(1-BP35/100) -> 14405468 | H35: =RANK(E36,E$2:E$49,1) -> 17 | I35: =RANK(G36,G$2:G$49,0) -> 7 | J35: =IFS(I36<=5,"High", I36<=15,"Moderate", TRUE,"Low") -> Low
A36: Angola | B36: AGO | C36: Access to electricity (% of population) | D36: EG.ELC.ACCS.ZS | E36: 51.1 | F36: Sub-Saharan Africa | G36: =VLOOKUP(B36,Population!A:B,2,FALSE)*(1-BP36/100) -> 36749906 | H36: =RANK(E37,E$2:E$49,1) -> 29 | I36: =RANK(G37,G$2:G$49,0) -> 25 | J36: =IFS(I37<=5,"High", I37<=15,"Moderate", TRUE,"Low") -> Low
A37: Rwanda | B37: RWA | C37: Access to electricity (% of population) | D37: EG.ELC.ACCS.ZS | E37: 63.9 | F37: Sub-Saharan Africa | G37: =VLOOKUP(B37,Population!A:B,2,FALSE)*(1-BP37/100) -> 13954471 | H37: =RANK(E38,E$2:E$49,1) -> 27 | I37: =RANK(G38,G$2:G$49,0) -> 38 | J37: =IFS(I38<=5,"High", I38<=15,"Moderate", TRUE,"Low") -> Moderate
A38: Lesotho | B38: LSO | C38: Access to electricity (% of population) | D38: EG.ELC.ACCS.ZS | E38: 57.3 | F38: Sub-Saharan Africa | G38: =VLOOKUP(B38,Population!A:B,2,FALSE)*(1-BP38/100) -> 2311472 | H38: =RANK(E39,E$2:E$49,1) -> 41 | I38: =RANK(G39,G$2:G$49,0) -> 8 | J38: =IFS(I39<=5,"High", I39<=15,"Moderate", TRUE,"Low") -> High
A39: Ghana | B39: GHA | C39: Access to electricity (% of population) | D39: EG.ELC.ACCS.ZS | E39: 89.5 | F39: Sub-Saharan Africa | G39: =VLOOKUP(B39,Population!A:B,2,FALSE)*(1-BP39/100) -> 33787914 | H39: =RANK(E40,E$2:E$49,1) -> 25 | I39: =RANK(G40,G$2:G$49,0) -> 2 | J39: =IFS(I40<=5,"High", I40<=15,"Moderate", TRUE,"Low") -> Moderate
... A83: Burkina Faso | B83: BFA | C83: Access to electricity (% of population) | D83: EG.ELC.ACCS.ZS | E83: 21.7 | F83: Sub-Saharan Africa | G83: =VLOOKUP(B83,Population!A:B,2,FALSE)*(1-BP83/100) -> 23025776 | H83: =RANK(E84,E$2:E$49,1) -> #N/A | I83: =RANK(G84,G$2:G$49,0) -> #N/A | J83: =IFS(I84<=5,"High", I84<=15,"Moderate", TRUE,"Low") -> High
A84: Data Source | B84: World Development Indicators
A86: Last Updated Date | B86: 46216
A88: Data Source | B88: World Development Indicators
A90: Last Updated Date | B90: 46216

Sheet Sheet5
A1: Country Name | B1: Access Rate | C1: Pop without Electricity
A2: Sierra Leone | B2: Access to electricity (% of population) | C2: 8460512
A3: Gambia, The | B3: Access to electricity (% of population) | C3: 2697845
A4: Eritrea | B4: Access to electricity (% of population) | C4: 3470390
A5: Mali | B5: Access to electricity (% of population) | C5: 23769127
A6: South Sudan | B6: Access to electricity (% of population) | C6: 11483374
A7: Botswana | B7: Access to electricity (% of population) | C7: 2480244
A8: Equatorial Guinea | B8: Access to electricity (% of population) | C8: 1847549
A9: Namibia | B9: Access to electricity (% of population) | C9: 2963095
A10: Mauritius | B10: Access to electricity (% of population) | C10: 1248647
A11: Comoros | B11: Access to electricity (% of population) | C11: 850387
A12: Cabo Verde | B12: Access to electricity (% of population) | C12: 522331
A13: Senegal | B13: Access to electricity (% of population) | C13: 18077573
... A41: Togo | B41: Access to electricity (% of population) | C41: 8223850
A42: Country Name | B42: Indicator Name | C42: Pop without Electricity
A43: Angola | B43: Access to electricity (% of population) | C43: 36749906
A44: Burundi | B44: Access to electricity (% of population) | C44: 13689450
A45: Benin | B45: Access to electricity (% of population) | C45: 14111034
A46: Burkina Faso | B46: Access to electricity (% of population) | C46: 23025776
A47: Data Source
A49: Last Updated Date | B49: 46216

Sheet Dashboard
A16: Top 5 Highest-Need Countries
A17: Madagascar
A18: Mauritius
A19: Eswatini
A20: Senegal
A21: Liberia

Sheet Population
A1: World Development Indicators
A2: 46216
A4: Country Code | B4: 2023
A5: ABW | B5: 107359 | C5: =VLOOKUP(B5, Population!A:B, 2, FALSE) * (1 - B5/100) -> #N/A
A6: AFE | B6: 750491370
A7: AFG | B7: 41454761
A8: AFW | B8: 508318102
A9: AGO | B9: 36749906
A10: ALB | B10: 2411658
A11: AND | B11: 80856
A12: ARB | B12: 482105978
A13: ARE | B13: 10483751
A14: ARG | B14: 45538401
A15: ARM | B15: 2964300
A16: ASM | B16: 47521
A17: ATG | B17: 93316
... A113: IND | B113: 1438069596
A114: INX
A115: IRL | B115: 5311538
A116: IRN | B116: 90608707
A117: IRQ | B117: 45074049
A118: ISL | B118: 385663
A119: ISR | B119: 9849000
A120: ITA | B120: 58984216
A121: JAM | B121: 2839786
A122: JOR | B122: 11439213
A123: JPN | B123: 124516650
A124: KAZ | B124: 20330104
A125: KEN | B125: 55339003
A126: KGZ | B126: 7099750
... A269: ZWE | B269: 16340822

Sheet Metadata
A1: Country Code | B1: Region | C1: IncomeGroup
A2: ABW | B2: Latin America & Caribbean | C2: High income
A3: AFE
A4: AFG | B4: Middle East & North Africa | C4: Low income
A5: AFW
A6: AGO | B6: Sub-Saharan Africa | C6: Lower middle income
A7: ALB | B7: Europe & Central Asia | C7: Upper middle income
A8: AND | B8: Europe & Central Asia | C8: High income
A9: ARB
A10: ARE | B10: Middle East & North Africa | C10: High income
A11: ARG | B11: Latin America & Caribbean | C11: Upper middle income
A12: ARM | B12: Europe & Central Asia | C12: Upper middle income
A13: ASM | B13: East Asia & Pacific | C13: High income
A14: ATG | B14: Latin America & Caribbean | C14: High income
A15: AUS | B15: East Asia & Pacific | C15: High income
A16: AUT | B16: Europe & Central Asia | C16: High income
A17: AZE | B17: Europe & Central Asia | C17: Upper middle income
A18: BDI | B18: Sub-Saharan Africa | C18: Low income
A19: BEL | B19: Europe & Central Asia | C19: High income
A20: BEN | B20: Sub-Saharan Africa | C20: Lower middle income
A21: BFA | B21: Sub-Saharan Africa | C21: Low income
... A37: CAN | B37: North America | C37: High income
A38: CEB
A39: CHE | B39: Europe & Central Asia | C39: High income
A40: CHI | B40: Europe & Central Asia | C40: High income
A41: CHL | B41: Latin America & Caribbean | C41: High income
A42: CHN | B42: East Asia & Pacific | C42: Upper middle income
A43: CIV | B43: Sub-Saharan Africa | C43: Lower middle income
A44: CMR | B44: Sub-Saharan Africa | C44: Lower middle income
A45: COD | B45: Sub-Saharan Africa | C45: Low income
A46: COG | B46: Sub-Saharan Africa | C46: Lower middle income
A47: COL | B47: Latin America & Caribbean | C47: Upper middle income
A48: COM | B48: Sub-Saharan Africa | C48: Lower middle income
A49: CPV | B49: Sub-Saharan Africa | C49: Upper middle income
A50: CRI | B50: Latin America & Caribbean | C50: High income
A51: CSS
A52: CUB | B52: Latin America & Caribbean | C52: Upper middle income
A53: CUW | B53: Latin America & Caribbean | C53: High income
A54: CYM | B54: Latin America & Caribbean | C54: High income
A55: CYP | B55: Europe & Central Asia | C55: High income
...
